Workbook

Sheet LCI
A1: Database | B1: OWM Facilities
A3: Activity | B3: Closed-tunnel Composter
A4: comment | B4: adapted from Lewerenz et al., 2023; represents montreal CTMO
A5: location | B5: CA-QC
A6: production amount | B6: 1
A7: unit | B7: tonne
A9: Exchanges
A10: name | B10: reference product | C10: unit | D10: amount | E10: location | F10: database | G10: type | H10: categories | I10: comment
A11: Closed-tunnel Composter | B11: OFMSW | C11: tonne | D11: 1 | E11: =B5 -> CA-QC | F11: =$B$1 -> OWM Facilities | G11: production | I11: output
A12: market for electricity, low voltage | B12: electricity, low voltage | C12: kilowatt hour | D12: =0.033*1000 -> 33 | E12: =B5 -> CA-QC | F12: ecoinvent-3.9.1-cutoff | G12: technosphere | I12: input
A13: market for machine operation, diesel, >= 74.57 kW, low load factor | B13: machine operation, diesel, >= 74.57 kW, low load factor | C13: hour | D13: =0.000253016462365506*1000 -> 0.25301646 | E13: GLO | F13: ecoinvent-3.9.1-cutoff | G13: technosphere | I13: input
A14: market for transport, freight, lorry >32 metric ton, EURO5 | B14: transport, freight, lorry >32 metric ton, EURO5 | C14: ton kilometer | D14: =Transportation!B15 -> 28.4 | E14: RER | F14: ecoinvent-3.9.1-cutoff | G14: technosphere | I14: input | J14: empty lorry km
A15: market for municipal solid waste | B15: municipal solid waste | C15: kilogram | D15: =0.0000185*1000 -> 0.0185 | E15: CA-QC | F15: ecoinvent-3.9.1-cutoff | G15: technosphere | I15: output
A16: treatment of wastewater, average, wastewater treatment | B16: wastewater, average | C16: cubic meter | D16: 0.225 | E16: CA-QC | F16: ecoinvent-3.9.1-cutoff | G16: technosphere | I16: output
A17: water | C17: cubic meter | D17: =0.000125*1000 -> 0.125 | F17: ecoinvent-3.9-biosphere | G17: biosphere | H17: air | I17: output, not sure if this is an elementary flow or technosphere, just said water
A18: Ammonia | C18: kilogram | D18: =0.0000376*1000 -> 0.0376 | F18: ecoinvent-3.9-biosphere | G18: biosphere | H18: air | I18: output
A19: Carbon dioxide, non-fossil | C19: kilogram | D19: =0.0936*1000 -> 93.6 | F19: ecoinvent-3.9-biosphere | G19: biosphere | H19: air | I19: output
A20: Dinitrogen monoxide | C20: kilogram | D20: =0.000091*1000 -> 0.091 | F20: ecoinvent-3.9-biosphere | G20: biosphere | H20: air | I20: output
A21: Hydrogen sulfide | C21: kilogram | D21: =0.000526*1000 -> 0.526 | F21: ecoinvent-3.9-biosphere | G21: biosphere | H21: air | I21: output
A22: Methane, non-fossil | C22: kilogram | D22: =0.00264*1000 -> 2.64 | F22: ecoinvent-3.9-biosphere | G22: biosphere | H22: air | I22: output
A23: NMVOC, non-methane volatile organic compounds | C23: kilogram | D23: =0.000476*1000 -> 0.476 | F23: ecoinvent-3.9-biosphere | G23: biosphere | H23: air | I23: output
A24: nutrient supply from urea | B24: inorganic nitrogen fertiliser, as N | C24: kilogram | D24: 0.295288 | E24: RNA | F24: ecoinvent-3.9.1-cutoff | G24: substitution
A25: nutrient supply from monoammonium phosphate | B25: inorganic phosphorus fertiliser, as P2O5 | C25: kilogram | D25: 0.168736 | E25: RNA | F25: ecoinvent-3.9.1-cutoff | G25: substitution
A26: nutrient supply from potassium nitrate | B26: inorganic potassium fertiliser, as K2O | C26: kilogram | D26: 0.253104 | E26: RNA | F26: ecoinvent-3.9.1-cutoff | G26: substitution
A36: Activity | B36: AD
A37: comment | B37: adapted from Lewerenz et al., 2023; represents montreal biomethanization plant
A38: location | B38: CA-QC
A39: production amount | B39: 1
A40: unit | B40: tonne
A42: Exchanges
A43: name | B43: reference product | C43: unit | D43: amount | E43: location | F43: database | G43: type | H43: categories | I43: comment
A44: AD | B44: OFMSW | C44: tonne | D44: 1 | E44: =B38 -> CA-QC | F44: =$B$1 -> OWM Facilities | G44: production
A45: market for electricity, low voltage | B45: electricity, low voltage | C45: kilowatt hour | D45: =1000*0.002135 -> 2.135 | E45: =E44 -> CA-QC | F45: ecoinvent-3.9.1-cutoff | G45: technosphere
A46: market for heat, central or small-scale, other than natural gas | B46: heat, central or small-scale, other than natural gas | C46: megajoule | D46: =1000*0.2416 -> 241.6 | E46: RoW | F46: ecoinvent-3.9.1-cutoff | G46: technosphere
A47: market for machine operation, diesel, >= 74.57 kW, low load factor | B47: machine operation, diesel, >= 74.57 kW, low load factor | C47: hour | D47: =1000*0.000352112676056338 -> 0.35211268 | E47: GLO | F47: ecoinvent-3.9.1-cutoff | G47: technosphere
A48: market for tap water | B48: tap water | C48: kilogram | D48: =1000*0.225 -> 225 | E48: CH | F48: ecoinvent-3.9.1-cutoff | G48: technosphere
A49: market for transport, freight, lorry >32 metric ton, EURO5 | B49: transport, freight, lorry >32 metric ton, EURO5 | C49: ton kilometer | D49: =Transportation!B16 -> 0 | E49: RER | F49: ecoinvent-3.9.1-cutoff | G49: technosphere
A50: Ammonia | C50: kilogram | D50: =1000*0.0001456 -> 0.1456 | F50: ecoinvent-3.9-biosphere | G50: biosphere | H50: air
A51: Carbon dioxide, non-fossil | C51: kilogram | D51: =1000*0.0916 -> 91.6 | F51: ecoinvent-3.9-biosphere | G51: biosphere | H51: air
A52: Dinitrogen monoxide | C52: kilogram | D52: =1000*0.00008 -> 0.08 | F52: ecoinvent-3.9-biosphere | G52: biosphere | H52: air
...

Sheet Comparing windrow models
A1: Windrow Compost | C1: Data source
A2: general name | C2: terrebonne | D2: NS | E2: lewerenz | F2: warm
A3: electricity, low voltage
A4: diesel
A5: wastewater
A6: municipal solid waste
A7: inorganic nitrogen fertiliser, as N
A8: inorganic phosphorus fertiliser, as P2O5
A9: inorganic potassium fertiliser, as K2O
A10: Carbon dioxide, non-fossil | C10: 0 | D10: 34.18291 | E10: 97.9
A11: Dinitrogen monoxide | C11: 1.3472482e-05 | D11: 8.9947156 | E11: =1000*0.00015225 -> 0.15225
A12: Methane, non-fossil | C12: 0.0026570728 | D12: 0.056084551 | E12: 3.24
A13: Ammonia
A14: NMVOC, non-methane volatile organic compounds
A15: Hydrogen sulfide
A19: Landfill | C19: terrebonne | D19: WARM (ghgs in kg) | E19: SETAC landfill | F19: ECCC (kg)
A20: transport, freight, lorry >32 metric ton, EURO5
A21: diesel (kg) | C21: 0.68883086 | D21: 230800 BTU
A22: Carbon | D22: =0.0807443330566553*0.90718474*1000 -> 73.250027 | E22: 73.250027
A23: Methane, from soil or biomass stock | D23: =0.0181205140326961*0.90718474*1000 -> 16.438654 | E23: 16.438654 | F23: 2.335523
A24: electricity generated | D24: =83.8075532188652*0.90718474 -> 76.028933
A25: market for natural gas, high pressure | C25: 109.57129
A26: CO2 | C26: 22.112567 | F26: 21.671377
A27: N2O | C27: 0.0053950635 | F27: 0.0051972445
A28: electricity consumed | C28: 36.273733

Sheet Transportation
A1: Transportation Distance | C1: Montreal-est TS Adress: | D1: 9000, place Marien, Montréal-Est
A2: note: assume all collection routes are the same and only consider distance from transfer station to facility, assume mtl-est transfer station (bc shared for both SSO and RW)
A3: Facility | B3: Distance | C3: units | D3: Address | E3: Note
A4: Landfill_saint sophie | B4: 50.7 | C4: km | D4: 2535, 1re Rue, Ste-Sophie (Qc) J0R 1S0
A5: Landfill_terrebonne | B5: 15.6 | C5: km | D5: 3779, chemin des 40 Arpents, Lachenaie, QC J6V 9T6
A6: Landfill_saint_thomas | B6: 59.6 | C6: km | D6: 1001, Chemin St-Joseph, Saint-Thomas, QC J0K 3L0
A7: Landfill_lachute | B7: 77.4 | C7: km | D7: 6985, chemin des Sources, Lachute
A9: Landfill_st-nicephore | B9: 120 | C9: km | D9: 25, rue Gagnon, St-Nicéphore (Qc) J2A 3H3
A10: Landfill_cecile_de_milton | B10: 86 | C10: km | D10: 702 route 137 sud, Sainte-Cécile-de-Milton, QC J0E 2C0
A11: Composter_casselman | B11: 170 | C11: km | D11: 908 Aurele Rd, Casselman, ON K0A 1M0 | E11: not sure…
A12: Composter_complexe enviro st Michel | B12: 13 | C12: km | D12: 2235 Rue Michel-Jurdant, Montréal, QC H1Z 4N1
A13: Composter_terrebonne | B13: 15.6 | C13: km | D13: =D5 -> 3779, chemin des 40 Arpents, Lachenaie, QC J6V 9T6
A14: Composter_saint thomas | B14: =B6 -> 59.6 | C14: km | D14: =D6 -> 1001, Chemin St-Joseph, Saint-Thomas, QC J0K 3L0 | E14: not sure…
A15: Closed-tunnel Composter | B15: 28.4 | C15: km | D15: 9091 Henri Bourassa Blvd W, Saint-Laurent, Quebec H4S 1P7 | E15: note: in reality I really don't think they would use the mtl est transfer station but why be specific for just this one
A16: AD | B16: 0 | C16: km | D16: can't find address currently

Sheet Landfill Equations (WARM)
A1: Warm model parameters (MSW landfilling of Mixed Organics; LFG recovery and electricity generation, typical collection, wet conditions (k=0.06))
A2: Process and parameters | B2: Equation (if applicable) | C2: Unit | D2: Value | E2: Notes | F2: Unit
A3: Electricity at grid | B3: electricity_from_CH4*CH4_recovered_for_energy*(1-system_down_time)*(final_yield_CH4*(1-moisture_content_mixed_organics)/tonne_to_sh_tn) | C3: kwh | D3: =D4*D5*(1-D6)*(D7*(1-D8)/D9) -> 87.325775
A4: electricity_from_CH4 | B4: CH4_calorific_value*net_capacity*kWh_per_BTU_CH4/(density_CH4_for_electricity/1000000) | D4: 3676.0684
A5: CH4_recovered_for_energy | D5: 0.49222093 | E5: %1. Source: Barlaz data
A6: system_down_time | D6: 0.03 | E6: 0.01
A7: final_yield_CH4 | B7: (1.24384729900016/GWP_CH4)*tonne_to_sh_tn/(1- moisture_content_mixed_organics) | D7: 0.15403929
A8: moisture_content_mixed_organics | D8: 0.64395917
A9: tonne_to_sh_tn | D9: 1.1023113 | E9: Conversion of units from metric tonnes to short tons
A10: CH4_calorific_value | D10: 1012 | E10: BTU/m3 methane. Source: EPA 2013. LMOP Benefits Calculator
A11: net_capacity | D11: 0.85 | E11: %1. Source: EPA 2005. LMOP Net capacity factor for generation units (availability, operating load, parasitic losses).
A12: density_CH4_for_electricity | D12: 20 | E12: g/ft3
A13: kWh_per_BTU_CH4 | D13: 8.5470085e-05 | E13: kWh of electricity generated per BTU methane. Source: EPA 2005. LMOP Benefits Calculator.
A14: GWP_CH4 | D14: 25 | E14: IPCC 2007
A15: Carbon | B15: C_storage_final *(1-moisture_content_mixed_organics)/tonne_to_sh_tn | D15: =D16 *(1-D8)/D9 -> 0.080744333 | E15: t
A16: C_storage_final | B16: 0.29606255454107*tonne_to_sh_tn/((1- moisture_content_mixed_organics)*C_to_CO2) | D16: 0.24998647
A17: C_to_CO2 | D17: 3.6666667 | E17: Conversion from carbon to CO2 according to molecular weights
A19: Methane | B19: CH4_emitted_final*final_yield_CH4*(1-moisture_content_mixed_organics)/tonne_to_sh_tn | D19: =D20*D7*(1-D8)/D9 -> 0.018120514 | E19: t
A20: CH4_emitted_final | D20: 0.36420295

Sheet Fertilizer credit for compost
A2: 1 | B2: t dry compost | G2: inorganic nitrogen fertiliser, as N | H2: nutrient supply from urea | I2: kilogram | J2: ='Fertilizer credit for compost'!A14 -> 0.295288 | K2: RNA | L2: ecoinvent-3.8-cutoff | M2: substitution | O2: output
A3: 2.5 | B3: t wet compost | G3: inorganic phosphorus fertiliser, as P2O5 | H3: nutrient supply from monoammonium phosphate | I3: kilogram | J3: ='Fertilizer credit for compost'!A12 -> 0.168736 | K3: RNA | L3: ecoinvent-3.8-cutoff | M3: substitution | O3: output
A4: 4 | B4: kg P2O5 | G4: inorganic potassium fertiliser, as K2O | H4: nutrient supply from potassium chloride | I4: kilogram | J4: ='Fertilizer credit for compost'!A13 -> 0.253104 | K4: RNA | L4: ecoinvent-3.8-cutoff | M4: substitution | O4: output
A5: 6 | B5: kg K2O
A6: 7 | B6: kg N
A8: source | B8: https://doi.org/10.1016/j.jclepro.2016.06.150
A9: Terrebonne compost
A10: 1 | B10: t OW
A11: 0.10546 | B11: t wet compost
A12: =$A$11/$A$3*A4 -> 0.168736 | B12: kg P2O5
A13: =$A$11/$A$3*A5 -> 0.253104 | B13: kg K2O
A14: =$A$11/$A$3*A6 -> 0.295288 | B14: kg N
A18: NS compost
A19: 1 | B19: t OW | G19: inorganic nitrogen fertiliser, as N | H19: nutrient supply from urea | I19: kilogram | J19: 1.7808 | K19: RNA | L19: ecoinvent-3.8-cutoff | M19: substitution | O19: output
A20: 0.636 | B20: t wet compost | G20: inorganic phosphorus fertiliser, as P2O5 | H20: nutrient supply from monoammonium phosphate | I20: kilogram | J20: 1.0176 | K20: RNA | L20: ecoinvent-3.8-cutoff | M20: substitution | O20: output
A21: =$A$20/$A$3*A4 -> 1.0176 | B21: kg P2O5 | G21: inorganic potassium fertiliser, as K2O | H21: nutrient supply from potassium chloride | I21: kilogram | J21: 1.5264 | K21: RNA | L21: ecoinvent-3.8-cutoff | M21: substitution | O21: output
A22: =$A$20/$A$3*A5 -> 1.5264 | B22: kg K2O
A23: =$A$20/$A$3*A6 -> 1.7808 | B23: kg N

Sheet Natural gas credit
B3: heating value | C3: units | D3: source
A4: Landfill gas | B4: 18.63 | C4: MJ/m3
A5: Natural gas | B5: 38.32 | C5: MJ/m3
A6: efficiency of LFG relative to NG | B6: =B4/B5 -> 0.4861691 | C6: %
A7: Annual production of GNR from AD | B7: 2579984 | C7: m3 | D7: GHG report City
A8: Facility capacity | B8: 60000 | C8: t OW annually | D8: sensitivity, 50, 60 %
A9: Annual production of RNG from landfill | B9: 225.37691 | C9: m3/ton OFMSW
A12: Avoided Natural gas AD | B12: =B7*B6/B8 -> 20.905142 | C12: m3/t OW
A13: Avoided Natural gas landfill | B13: =B9*B6 -> 109.57129 | C13: m3/t OW
