Workbook

Sheet LCI
A1: Database | B1: OWM Facilities
A26: Activity | B26: Closed-tunnel Composter (literature)
A27: comment | B27: adapted from Lewerenz et al., 2023; represents montreal CTMO
A28: location | B28: CA-QC
A29: production amount | B29: 1
A30: unit | B30: tonne
A32: Exchanges
A33: name | B33: reference product | C33: unit | D33: amount | E33: location | F33: database | G33: type | H33: categories | I33: comment
A34: Closed-tunnel Composter (literature) | B34: OFMSW | C34: tonne | D34: 1 | E34: =B28 -> CA-QC | F34: =$B$1 -> OWM Facilities | G34: production | I34: output
A35: market for electricity, low voltage | B35: electricity, low voltage | C35: kilowatt hour | D35: =0.033*1000 -> 33 | E35: =B28 -> CA-QC | F35: ecoinvent-3.9.1-cutoff | G35: technosphere | I35: input
A36: market for machine operation, diesel, >= 74.57 kW, low load factor | B36: machine operation, diesel, >= 74.57 kW, low load factor | C36: hour | D36: =0.000253016462365506*1000 -> 0.25301646 | E36: GLO | F36: ecoinvent-3.9.1-cutoff | G36: technosphere | I36: input
A37: market for transport, freight, lorry >32 metric ton, EURO5 | B37: transport, freight, lorry >32 metric ton, EURO5 | C37: ton kilometer | D37: =Transportation!B14 -> 0 | E37: RER | F37: ecoinvent-3.9.1-cutoff | G37: technosphere | I37: input | J37: empty lorry km
A38: market for municipal solid waste | B38: municipal solid waste | C38: kilogram | D38: =0.0000185*1000 -> 0.0185 | E38: CA-QC | F38: ecoinvent-3.9.1-cutoff | G38: technosphere | I38: output
A39: treatment of wastewater, average, wastewater treatment | B39: wastewater, average | C39: cubic meter | D39: -0.225 | E39: CA-QC | F39: ecoinvent-3.9.1-cutoff | G39: technosphere | I39: output
A40: water | C40: cubic meter | D40: =0.000125*1000 -> 0.125 | F40: ecoinvent-3.9-biosphere | G40: biosphere | H40: air | I40: output, not sure if this is an elementary flow or technosphere, just said water
A41: Ammonia | C41: kilogram | D41: =0.0000376*1000 -> 0.0376 | F41: ecoinvent-3.9-biosphere | G41: biosphere | H41: air | I41: output
A42: Carbon dioxide, non-fossil | C42: kilogram | D42: =0.0936*1000 -> 93.6 | F42: ecoinvent-3.9-biosphere | G42: biosphere | H42: air | I42: output
A43: Dinitrogen monoxide | C43: kilogram | D43: =0.000091*1000 -> 0.091 | F43: ecoinvent-3.9-biosphere | G43: biosphere | H43: air | I43: output
A44: Hydrogen sulfide | C44: kilogram | D44: =0.000526*1000 -> 0.526 | F44: ecoinvent-3.9-biosphere | G44: biosphere | H44: air | I44: output
A45: Methane, non-fossil | C45: kilogram | D45: =0.00264*1000 -> 2.64 | F45: ecoinvent-3.9-biosphere | G45: biosphere | H45: air | I45: output
A46: NMVOC, non-methane volatile organic compounds | C46: kilogram | D46: =0.000476*1000 -> 0.476 | F46: ecoinvent-3.9-biosphere | G46: biosphere | H46: air | I46: output
A47: nutrient supply from urea | B47: inorganic nitrogen fertiliser, as N | C47: kilogram | D47: 0.295288 | E47: RNA | F47: ecoinvent-3.9.1-cutoff | G47: substitution
A48: nutrient supply from monoammonium phosphate | B48: inorganic phosphorus fertiliser, as P2O5 | C48: kilogram | D48: 0.168736 | E48: RNA | F48: ecoinvent-3.9.1-cutoff | G48: substitution
A49: nutrient supply from potassium nitrate | B49: inorganic potassium fertiliser, as K2O | C49: kilogram | D49: 0.253104 | E49: RNA | F49: ecoinvent-3.9.1-cutoff | G49: substitution
A59: Activity | B59: AD_literature
A60: comment | B60: adapted from Lewerenz et al., 2023; represents montreal biomethanization plant
A61: location | B61: CA-QC
A62: production amount | B62: 1
A63: unit | B63: tonne
A65: Exchanges
A66: name | B66: reference product | C66: unit | D66: amount | E66: location | F66: database | G66: type | H66: categories | I66: comment
A67: =B59 -> AD_literature | B67: OFMSW | C67: tonne | D67: 1 | E67: =B61 -> CA-QC | F67: =$B$1 -> OWM Facilities | G67: production
A68: market for electricity, low voltage | B68: electricity, low voltage | C68: kilowatt hour | D68: =1000*0.002135 -> 2.135 | E68: =E67 -> CA-QC | F68: ecoinvent-3.9.1-cutoff | G68: technosphere
A69: market for heat, central or small-scale, other than natural gas | B69: heat, central or small-scale, other than natural gas | C69: megajoule | D69: =1000*0.2416 -> 241.6 | E69: RoW | F69: ecoinvent-3.9.1-cutoff | G69: technosphere
A70: market for machine operation, diesel, >= 74.57 kW, low load factor | B70: machine operation, diesel, >= 74.57 kW, low load factor | C70: hour | D70: =1000*0.000352112676056338 -> 0.35211268 | E70: GLO | F70: ecoinvent-3.9.1-cutoff | G70: technosphere
A71: market for tap water | B71: tap water | C71: kilogram | D71: =1000*0.225 -> 225 | E71: CH | F71: ecoinvent-3.9.1-cutoff | G71: technosphere
A72: market for transport, freight, lorry >32 metric ton, EURO5 | B72: transport, freight, lorry >32 metric ton, EURO5 | C72: ton kilometer | D72: =Transportation!B15 -> 0 | E72: RER | F72: ecoinvent-3.9.1-cutoff | G72: technosphere
A73: Ammonia | C73: kilogram | D73: =1000*0.0001456 -> 0.1456 | F73: ecoinvent-3.9-biosphere | G73: biosphere | H73: air
A74: Carbon dioxide, non-fossil | C74: kilogram | D74: =1000*0.0916 -> 91.6 | F74: ecoinvent-3.9-biosphere | G74: biosphere | H74: air
A75: Dinitrogen monoxide | C75: kilogram | D75: =1000*0.00008 -> 0.08 | F75: ecoinvent-3.9-biosphere | G75: biosphere | H75: air
...

Sheet Comparing models
A1: Windrow Compost | D1: Data source
A2: general name | C2: terrebonne new | D2: terrebonne old | E2: NS | F2: lewerenz | G2: boldrin | H2: city (AD) | I2: city (compost)
A3: electricity, low voltage
A4: diesel
A5: wastewater
A6: municipal solid waste
A7: inorganic nitrogen fertiliser, as N
A8: inorganic phosphorus fertiliser, as P2O5
A9: inorganic potassium fertiliser, as K2O
A10: Carbon dioxide, non-fossil | D10: 0 | E10: 34.18291 | F10: 97.9
A11: Dinitrogen monoxide | C11: 0.22454136 | D11: 1.3472482e-05 | E11: 8.9947156 | F11: =1000*0.00015225 -> 0.15225 | H11: 0.0016666667 | I11: 0.20508104
A12: Methane, non-fossil | C12: 1.6279249 | D12: 0.0026570728 | E12: 0.056084551 | F12: 3.24 | H12: 0.0016666667
A13: Ammonia
A14: NMVOC, non-methane volatile organic compounds
A15: Hydrogen sulfide
A19: Landfill | C19: terrebonne marwan OF | D19: terrebonne my OF | E19: WARM (ghgs in kg) | F19: SETAC landfill | G19: ECCC (kg)
A20: transport, freight, lorry >32 metric ton, EURO5
A21: diesel (kg) | C21: 0.68883086 | D21: 0.68883086 | E21: =230800*I24*I26/1000*840 -> 5.2763314 | H21: for warm diesel is in BTU
A22: Carbon (kg) | E22: =0.08074*I24*1000 -> 73.246093 | F22: 73.250027
A23: Methane, from soil or biomass stock (kg) | C23: 44.25023 | E23: =0.01598*I24*1000 -> 14.496812 | F23: 16.438654 | G23: 2.335523 | I23: sh tn to t | J23: source
A24: electricity generated (kwh) | E24: =89.18599*I24 -> 80.908166 | I24: 0.9071847 | J24: https://www.eia.gov/tools/faqs/faq.php?id=7&t=2
A25: market for natural gas, high pressure | C25: 109.57129 | D25: 109.57129 | I25: 1 btu in litres | J25: source
A26: CO2 | C26: 410.599 | D26: 22.112567 | G26: 21.671377 | I26: 3e-05 | J26: https://www.eia.gov/energyexplained/units-and-calculators/energy-conversion-calculators.php
A27: N2O | C27: 0.098470135 | D27: 0.0053950635 | G27: 0.0051972445 | I27: density | J27: https://www.ic.gc.ca/eic/site/mc-mc.nsf/vwapj/VCF_Diesel.pdf/$file/VCF_Diesel.pdf
A28: electricity consumed | C28: 36.273733 | D28: 36.273733 | I28: 840 | J28: kg/m3
A31: Fertilizer credit | D31: quality sheet compost | E31: quality sheet AD | F31: literature compost | G31: literature digestate | H31: NS | I31: unit
A32: nutrient supply from urea | B32: inorganic nitrogen fertiliser, as N | D32: 2.3344288 | E32: 8.3638 | F32: 0.295288 | G32: =620*0.4 -> 248 | H32: 1.7808 | I32: kg
A33: nutrient supply from monoammonium phosphate | B33: inorganic phosphorus fertiliser, as P2O5 | D33: 0.62187653 | E33: 8.835 | F33: 0.168736 | H33: 1.0176 | I33: kg
A34: nutrient supply from potassium nitrate | B34: inorganic potassium fertiliser, as K2O | D34: 0.014530974 | E34: 0.7657 | F34: 0.253104 | H34: 1.5264 | I34: kg

Sheet GHGRP Landfill Gas Inventory
J3: 0725 organic waste | K3: 313091.04
A4: Landfill Name | B4: Current LFG Management System (2024) | C4: GHGRP ID | D4: NPRI ID | F4: Lachenaie/Terrebonne | J4: Lachenaie organic waste | K4: 29349 | L4: Lachute
A5: Complexe Enviro Connexions | B5: RNG | C5: G10401 | D5: 6370 | J5: annual organic waste = | K5: 556063.89
A6: LET de Lachute | B6: Electricity | C6: G10538 | D6: 27915 | F6: Gas | G6: Sum (tonnes) | H6: Sum (tonnes CO2 eq ) | J6: tonnes/tonne organic waste in landfill | L6: Gas | M6: Sum (tonnes) | N6: Sum (tonnes CO2 eq ) | R6: =A7 -> LET de Ste-Sophie
A7: LET de Ste-Sophie | B7: Direct Use (RNG under development) | C7: G10344 | D7: 6173 | F7: CO2 | G7: 12050.67 | H7: 12 051 | J7: =G7/$K$3*1000 -> 38.489348 | K7: kg/tonne OFMSW | L7: CO2 | M7: 1 174.32 | N7: 1 174 | R7: Gas | S7: Sum (tonnes) | T7: Sum (tonnes CO2 eq )
A8: LET de St-Nicéphore | B8: Electricity | C8: G10572 | D8: 6171 | F8: CH4 | G8: 1298.7 | H8: 36 364 | J8: =G8/$K$3*1000 -> 4.1479948 | K8: kg/tonne OFMSW | L8: CH4 | M8: 5 773.59 | N8: 161 660 | R8: CO2 | S8: 2 621.54 | T8: 2 622
A9: LET de St-Thomas (Rive-Nord) | B9: RNG | C9: G10730 | F9: N2O | G9: 2.89 | H9: 766 | J9: =G9/$K$3*1000 -> 0.0092305421 | K9: kg/tonne OFMSW | L9: N2O | M9: 0.01 | N9: 2 | R9: CH4 | S9: 5 744.96 | T9: 160 859
A10: LET Roland Thibault Inc | B10: Electricity | C10: G10633 | D10: 31585 | F10: HFCs | G10: 0 | H10: 0 | L10: HFCs | M10: 0 | N10: 0 | R10: N2O | S10: 0.03 | T10: 7
F11: PFCs | G11: 0 | H11: 0 | L11: PFCs | M11: 0 | N11: 0 | R11: HFCs | S11: 0 | T11: 0
F12: SF6 | G12: 0 | H12: 0 | L12: SF6 | M12: 0 | N12: 0 | R12: PFCs | S12: 0 | T12: 0
F13: Total : | H13: 49 180 | L13: Total : | N13: 162 837 | R13: SF6 | S13: 0 | T13: 0
R14: Total : | T14: 163 487
F18: =A8 -> LET de St-Nicéphore | L18: =A9 -> LET de St-Thomas (Rive-Nord)
F19: Gas | G19: Sum (tonnes) | H19: Sum (tonnes CO2 eq ) | L19: Gas | M19: Sum (tonnes) | N19: Sum (tonnes CO2 eq )
F20: CO2 | G20: 1 454.46 | H20: 1 454 | L20: CO2 | M20: 4 298.36 | N20: 4 298
F21: CH4 | G21: 5 372.87 | H21: 150 440 | L21: CH4 | M21: 1 277.00 | N21: 35 756
F22: N2O | G22: 0.39 | H22: 103 | L22: N2O | M22: 1.28 | N22: 338
F23: HFCs | G23: 0 | H23: 0 | L23: HFCs | M23: 0 | N23: 0
F24: PFCs | G24: 0 | H24: 0 | L24: PFCs | M24: 0 | N24: 0
F25: SF6 | G25: 0 | H25: 0 | L25: SF6 | M25: 0 | N25: 0
F26: Total : | H26: 151 998 | L26: Total : | N26: 40 393
F29: =A10 -> LET Roland Thibault Inc
F30: Gas | G30: Sum (tonnes) | H30: Sum (tonnes CO2 eq )

Sheet Transportation
A1: Transportation Distance | C1: Montreal-est TS Adress: | D1: 9000, place Marien, Montréal-Est
A3: Facility | B3: Distance | C3: units | D3: Address | E3: Note
A4: Landfill_saint sophie | B4: 45 | C4: km | D4: N/A | E4: Obtained from 2024 report from the City of Montreal
A5: Landfill_terrebonne | B5: 32 | C5: km | D5: N/A | E5: Obtained from 2024 report from the City of Montreal
A6: Landfill_saint_thomas | B6: 74 | C6: km | D6: N/A | E6: Obtained from 2024 report from the City of Montreal
A7: Landfill_lachute | B7: 77.4 | C7: km | D7: 6985, chemin des Sources, Lachute | E7: Distance on google maps from Montreal-Est transfer station to Lachute Landfill
A8: Landfill_st-nicephore | B8: 123 | C8: km | D8: N/A | E8: Obtained from 2024 report from the City of Montreal
A9: Landfill_cecile_de_milton | B9: 96 | C9: km | D9: N/A | E9: Obtained from 2024 report from the City of Montreal
A10: Composter_casselman | B10: 133 | C10: km | D10: N/A | E10: Obtained from 2024 report from the City of Montreal
A11: Composter_complexe enviro st Michel | B11: 6 | C11: km | D11: N/A | E11: Obtained from 2024 report from the City of Montreal
A12: Composter_terrebonne | B12: 32 | C12: km | D12: N/A | E12: Obtained from 2024 report from the City of Montreal
A13: Composter_saint thomas | B13: 74 | C13: km | D13: N/A | E13: Obtained from 2024 report from the City of Montreal
A14: Closed-tunnel Composter | B14: 0 | C14: km | D14: N/A | E14: Obtained from 2024 report from the City of Montreal
A15: AD | B15: 0 | C15: km | D15: N/A | E15: Obtained from 2024 report from the City of Montreal

Sheet Landfill Equations (WARM)
A1: Warm model parameters (MSW landfilling of Mixed Organics; LFG recovery and electricity generation, typical collection, wet conditions (k=0.06))
A2: Process and parameters | B2: Equation (if applicable) | C2: Unit | D2: Value | E2: Notes | F2: Unit
A3: Electricity at grid | B3: electricity_from_CH4*CH4_recovered_for_energy*(1-system_down_time)*(final_yield_CH4*(1-moisture_content_mixed_organics)/tonne_to_sh_tn) | C3: kwh | D3: =D4*D5*(1-D6)*(D7*(1-D8)/D9) -> 87.325775
A4: electricity_from_CH4 | B4: CH4_calorific_value*net_capacity*kWh_per_BTU_CH4/(density_CH4_for_electricity/1000000) | D4: 3676.0684
A5: CH4_recovered_for_energy | D5: 0.49222093 | E5: %1. Source: Barlaz data
A6: system_down_time | D6: 0.03 | E6: 0.01
A7: final_yield_CH4 | B7: (1.24384729900016/GWP_CH4)*tonne_to_sh_tn/(1- moisture_content_mixed_organics) | D7: 0.15403929
A8: moisture_content_mixed_organics | D8: 0.64395917
A9: tonne_to_sh_tn | D9: 1.1023113 | E9: Conversion of units from metric tonnes to short tons
A10: CH4_calorific_value | D10: 1012 | E10: BTU/m3 methane. Source: EPA 2013. LMOP Benefits Calculator
A11: net_capacity | D11: 0.85 | E11: %1. Source: EPA 2005. LMOP Net capacity factor for generation units (availability, operating load, parasitic losses).
A12: density_CH4_for_electricity | D12: 20 | E12: g/ft3
A13: kWh_per_BTU_CH4 | D13: 8.5470085e-05 | E13: kWh of electricity generated per BTU methane. Source: EPA 2005. LMOP Benefits Calculator.
A14: GWP_CH4 | D14: 25 | E14: IPCC 2007
A15: Carbon | B15: C_storage_final *(1-moisture_content_mixed_organics)/tonne_to_sh_tn | D15: =D16 *(1-D8)/D9 -> 0.080744333 | E15: t
A16: C_storage_final | B16: 0.29606255454107*tonne_to_sh_tn/((1- moisture_content_mixed_organics)*C_to_CO2) | D16: 0.24998647
A17: C_to_CO2 | D17: 3.6666667 | E17: Conversion from carbon to CO2 according to molecular weights
A19: Methane | B19: CH4_emitted_final*final_yield_CH4*(1-moisture_content_mixed_organics)/tonne_to_sh_tn | D19: =D20*D7*(1-D8)/D9 -> 0.018120514 | E19: t
A20: CH4_emitted_final | D20: 0.36420295

Sheet Natural gas credit
B3: heating value | C3: units | D3: source
A4: Landfill gas | B4: 18.63 | C4: MJ/m3
A5: Natural gas | B5: 38.32 | C5: MJ/m3
A6: efficiency of LFG relative to NG | B6: =B4/B5 -> 0.4861691 | C6: %
A7: Annual production of GNR from AD | B7: 2579984 | C7: m3 | D7: GHG report City
A8: Facility capacity | B8: 60000 | C8: t OW annually | D8: sensitivity, 50, 60 %
A9: Annual production of RNG from landfill | B9: 400.27963 | C9: m3/ton OFMSW
A10: Annual production of RNG from AD | B10: =B7/B8 -> 42.999733 | C10: m3/ton OFMSW
G11: =2649/B9 -> 6.6178737 | H11: MJ/m3 | I11: LFG heating value
A12: Avoided Natural gas AD | B12: =B7*B6/B8 -> 20.905142 | C12: m3/t OW
A13: Avoided Natural gas landfill | B13: =B9*B6 -> 194.60359 | C13: m3/t OW

Sheet Fertilizer credit for compost
C1: compost ontario | D1: city compost final | F1: digestate
C2: on a wet basis | D2: 0.23 | E2: moisture content | F2: 0.81 | G2: moisture content
A3: 1 | B3: t dry compost | D3: 1 | E3: t dry compost | F3: 1 | G3: t dry digestate | I3: inorganic nitrogen fertiliser, as N | J3: nutrient supply from urea | K3: kilogram | L3: ='Fertilizer credit for compost'!A15 -> 0.295288 | M3: RNA | N3: ecoinvent-3.8-cutoff | O3: substitution | Q3: output
A4: 2.5 | B4: t wet compost | C4: 1 | D4: =D3/(1-D2) -> 1.2987013 | E4: t wet compost | F4: =F3/(1-F2) -> 5.2631579 | G4: t wet digestate | I4: inorganic phosphorus fertiliser, as P2O5 | J4: nutrient supply from monoammonium phosphate | K4: kilogram | L4: ='Fertilizer credit for compost'!A13 -> 0.168736 | M4: RNA | N4: ecoinvent-3.8-cutoff | O4: substitution | Q4: output
A5: 4 | B5: kg P2O5 | C5: =13*0.4536 -> 5.8968 | D5: =6190/1000 -> 6.19 | E5: kg P2O5 | F5: =75000*(1000/(10^6)) -> 75 | G5: kg P2O5 | I5: inorganic potassium fertiliser, as K2O | J5: nutrient supply from potassium chloride | K5: kilogram | L5: ='Fertilizer credit for compost'!A14 -> 0.253104 | M5: RNA | N5: ecoinvent-3.8-cutoff | O5: substitution | Q5: output
A6: 6 | B6: kg K2O | C6: =16*0.4536 -> 7.2576 | D6: =9710/1000 -> 9.71 | E6: kg K2O | F6: =6500*(1000/(10^6)) -> 6.5 | G6: kg K2O
A7: 7 | B7: kg N | C7: =48.8*0.4536 -> 22.13568 | D7: =17/1000 -> 0.017 | E7: kg N/ t dry compost | F7: =71000*(1000/(10^6)) -> 71 | G7: kg N/ t dry compst
A9: source | B9: https://doi.org/10.1016/j.jclepro.2016.06.150
A10: Terrebonne compost
A11: 1 | B11: t OW
A12: 0.10546 | B12: t wet compost
A13: =$A$12/$A$4*A5 -> 0.168736 | B13: kg P2O5
A14: =$A$12/$A$4*A6 -> 0.253104 | B14: kg K2O
A15: =$A$12/$A$4*A7 -> 0.295288 | B15: kg N
A19: NS compost
A20: 1 | B20: t OW | I20: inorganic nitrogen fertiliser, as N | J20: nutrient supply from urea | K20: kilogram | L20: 1.7808 | M20: RNA | N20: ecoinvent-3.8-cutoff | O20: substitution | Q20: output
A21: 0.636 | B21: t wet compost | I21: inorganic phosphorus fertiliser, as P2O5 | J21: nutrient supply from monoammonium phosphate | K21: kilogram | L21: 1.0176 | M21: RNA | N21: ecoinvent-3.8-cutoff | O21: substitution | Q21: output
A22: =$A$21/$A$4*A5 -> 1.0176 | B22: kg P2O5 | I22: inorganic potassium fertiliser, as K2O | J22: nutrient supply from potassium chloride | K22: kilogram | L22: 1.5264 | M22: RNA | N22: ecoinvent-3.8-cutoff | O22: substitution | Q22: output
A23: =$A$21/$A$4*A6 -> 1.5264 | B23: kg K2O
A24: =$A$21/$A$4*A7 -> 1.7808 | B24: kg N
A27: nutrient sheets
A28: compost
A29: 1 | B29: t OW
A30: 0.10546 | B30: t wet compost
A31: =A30*C7 -> 2.3344288 | B31: kg N
A32: =A30*C5 -> 0.62187653 | B32: kg P2O5
A33: =A30/C6 -> 0.014530974 | B33: kg K2O
A35: digestate
A36: 1 | B36: t OW
A37: 0.235 | B37: t wet digestate
A38: =A37/F4*F7 -> 3.17015 | B38: kg N
A39: =A37/F4*F5 -> 3.34875 | B39: kg P2O5
A40: =A37/F4*F6 -> 0.290225 | B40: kg K2O
A42: city compost | I42: inorganic nitrogen fertiliser, as N | K42: kg | L42: 497.44003
A43: 1 | B43: =B36 -> t OW | I43: inorganic phosphorus fertiliser, as P2O5 | K43: kg | L43: 181126.69
A44: 0.17406036 | B44: =B30 -> t wet compost | C44: =A44*1000 -> 174.06036 | I44: inorganic potassium fertiliser, as K2O | K44: kg | L44: 284126.04
A45: =A44*C7 -> 3.8529443 | B45: kg N
A46: =A44*C5 -> 1.0263991 | B46: kg P2O5
A47: =A44*C6 -> 1.2632604 | B47: kg K2O
A50: city compost final | B50: 1 t OW
...
