Workbook

Sheet LCI
A1: Database | B1: SA OWM Facilities
A3: Activity | B3: Closed-tunnel Composter (literature)
A4: comment | B4: adapted from Lewerenz et al., 2023; represents montreal CTMO
A5: location | B5: CA-QC
A6: production amount | B6: 1
A7: unit | B7: tonne
A9: Exchanges
A10: name | B10: reference product | C10: unit | D10: amount | E10: location | F10: database | G10: type | H10: categories | I10: comment
A11: Closed-tunnel Composter (literature) | B11: OFMSW | C11: tonne | D11: 1 | E11: =B5 -> CA-QC | F11: =$B$1 -> SA OWM Facilities | G11: production | I11: output
A12: market for electricity, low voltage | B12: electricity, low voltage | C12: kilowatt hour | D12: =0.033*1000 -> 33 | E12: =B5 -> CA-QC | F12: ecoinvent-3.9.1-cutoff | G12: technosphere | I12: input
A13: market for machine operation, diesel, >= 74.57 kW, low load factor | B13: machine operation, diesel, >= 74.57 kW, low load factor | C13: hour | D13: =0.000253016462365506*1000 -> 0.25301646 | E13: GLO | F13: ecoinvent-3.9.1-cutoff | G13: technosphere | I13: input
A14: market for transport, freight, lorry >32 metric ton, EURO5 | B14: transport, freight, lorry >32 metric ton, EURO5 | C14: ton kilometer | D14: =Transportation!B14 -> 0 | E14: RER | F14: ecoinvent-3.9.1-cutoff | G14: technosphere | I14: input | J14: empty lorry km
A15: market for municipal solid waste | B15: municipal solid waste | C15: kilogram | D15: =0.0000185*1000 -> 0.0185 | E15: CA-QC | F15: ecoinvent-3.9.1-cutoff | G15: technosphere | I15: output
A16: treatment of wastewater, average, wastewater treatment | B16: wastewater, average | C16: cubic meter | D16: -0.225 | E16: CA-QC | F16: ecoinvent-3.9.1-cutoff | G16: technosphere | I16: output
A17: water | C17: cubic meter | D17: =0.000125*1000 -> 0.125 | F17: ecoinvent-3.9-biosphere | G17: biosphere | H17: air | I17: output, not sure if this is an elementary flow or technosphere, just said water
A18: Ammonia | C18: kilogram | D18: =0.0000376*1000 -> 0.0376 | F18: ecoinvent-3.9-biosphere | G18: biosphere | H18: air | I18: output
A19: Carbon dioxide, non-fossil | C19: kilogram | D19: =0.0936*1000 -> 93.6 | F19: ecoinvent-3.9-biosphere | G19: biosphere | H19: air | I19: output
A20: Dinitrogen monoxide | C20: kilogram | D20: =0.000091*1000 -> 0.091 | F20: ecoinvent-3.9-biosphere | G20: biosphere | H20: air | I20: output
A21: Hydrogen sulfide | C21: kilogram | D21: =0.000526*1000 -> 0.526 | F21: ecoinvent-3.9-biosphere | G21: biosphere | H21: air | I21: output
A22: Methane, non-fossil | C22: kilogram | D22: =0.00264*1000 -> 2.64 | F22: ecoinvent-3.9-biosphere | G22: biosphere | H22: air | I22: output
A23: NMVOC, non-methane volatile organic compounds | C23: kilogram | D23: =0.000476*1000 -> 0.476 | F23: ecoinvent-3.9-biosphere | G23: biosphere | H23: air | I23: output
A24: nutrient supply from urea | B24: inorganic nitrogen fertiliser, as N | C24: kilogram | D24: 0.295288 | E24: RNA | F24: ecoinvent-3.9.1-cutoff | G24: substitution
A25: nutrient supply from monoammonium phosphate | B25: inorganic phosphorus fertiliser, as P2O5 | C25: kilogram | D25: 0.168736 | E25: RNA | F25: ecoinvent-3.9.1-cutoff | G25: substitution
A26: nutrient supply from potassium nitrate | B26: inorganic potassium fertiliser, as K2O | C26: kilogram | D26: 0.253104 | E26: RNA | F26: ecoinvent-3.9.1-cutoff | G26: substitution
A36: Activity | B36: AD_literature
A37: comment | B37: adapted from Lewerenz et al., 2023; represents montreal biomethanization plant
A38: location | B38: CA-QC
A39: production amount | B39: 1
A40: unit | B40: tonne
A42: Exchanges
A43: name | B43: reference product | C43: unit | D43: amount | E43: location | F43: database | G43: type | H43: categories | I43: comment
A44: =B36 -> AD_literature | B44: OFMSW | C44: tonne | D44: 1 | E44: =B38 -> CA-QC | F44: =$B$1 -> SA OWM Facilities | G44: production
A45: market for electricity, low voltage | B45: electricity, low voltage | C45: kilowatt hour | D45: =1000*0.002135 -> 2.135 | E45: =E44 -> CA-QC | F45: ecoinvent-3.9.1-cutoff | G45: technosphere
A46: market for heat, central or small-scale, other than natural gas | B46: heat, central or small-scale, other than natural gas | C46: megajoule | D46: =1000*0.2416 -> 241.6 | E46: RoW | F46: ecoinvent-3.9.1-cutoff | G46: technosphere
A47: market for machine operation, diesel, >= 74.57 kW, low load factor | B47: machine operation, diesel, >= 74.57 kW, low load factor | C47: hour | D47: =1000*0.000352112676056338 -> 0.35211268 | E47: GLO | F47: ecoinvent-3.9.1-cutoff | G47: technosphere
A48: market for tap water | B48: tap water | C48: kilogram | D48: =1000*0.225 -> 225 | E48: CH | F48: ecoinvent-3.9.1-cutoff | G48: technosphere
A49: market for transport, freight, lorry >32 metric ton, EURO5 | B49: transport, freight, lorry >32 metric ton, EURO5 | C49: ton kilometer | D49: =Transportation!B15 -> 0 | E49: RER | F49: ecoinvent-3.9.1-cutoff | G49: technosphere
A50: Ammonia | C50: kilogram | D50: =1000*0.0001456 -> 0.1456 | F50: ecoinvent-3.9-biosphere | G50: biosphere | H50: air
A51: Carbon dioxide, non-fossil | C51: kilogram | D51: =1000*0.0916 -> 91.6 | F51: ecoinvent-3.9-biosphere | G51: biosphere | H51: air
A52: Dinitrogen monoxide | C52: kilogram | D52: =1000*0.00008 -> 0.08 | F52: ecoinvent-3.9-biosphere | G52: biosphere | H52: air
...

Sheet Comparing models
A1: Windrow Compost | D1: Data source
A2: general name | C2: terrebonne new | D2: terrebonne old | E2: NS | F2: lewerenz | G2: boldrin | H2: city (AD) | I2: city (compost)
A3: electricity, low voltage
A4: diesel
A5: wastewater
A6: municipal solid waste
A7: inorganic nitrogen fertiliser, as N
A8: inorganic phosphorus fertiliser, as P2O5
A9: inorganic potassium fertiliser, as K2O
A10: Carbon dioxide, non-fossil | D10: 0 | E10: 34.18291 | F10: 97.9
A11: Dinitrogen monoxide | C11: 0.22454136 | D11: 1.3472482e-05 | E11: 8.9947156 | F11: =1000*0.00015225 -> 0.15225 | H11: 0.0016666667 | I11: 0.20508104
A12: Methane, non-fossil | C12: 1.6279249 | D12: 0.0026570728 | E12: 0.056084551 | F12: 3.24 | H12: 0.0016666667
A13: Ammonia
A14: NMVOC, non-methane volatile organic compounds
A15: Hydrogen sulfide
A19: Landfill | C19: terrebonne marwan OF | D19: terrebonne my OF | E19: WARM (ghgs in kg) | F19: SETAC landfill | G19: ECCC (kg)
A20: transport, freight, lorry >32 metric ton, EURO5
A21: diesel (kg) | C21: 0.68883086 | D21: 0.68883086 | E21: =230800*I24*I26/1000*840 -> 5.2763314 | H21: for warm diesel is in BTU
A22: Carbon (kg) | E22: =0.08074*I24*1000 -> 73.246093 | F22: 73.250027
A23: Methane, from soil or biomass stock (kg) | C23: 44.25023 | E23: =0.01598*I24*1000 -> 14.496812 | F23: 16.438654 | G23: 2.335523 | I23: sh tn to t | J23: source
A24: electricity generated (kwh) | E24: =89.18599*I24 -> 80.908166 | I24: 0.9071847 | J24: https://www.eia.gov/tools/faqs/faq.php?id=7&t=2
A25: market for natural gas, high pressure | C25: 109.57129 | D25: 109.57129 | I25: 1 btu in litres | J25: source
A26: CO2 | C26: 410.599 | D26: 22.112567 | G26: 21.671377 | I26: 3e-05 | J26: https://www.eia.gov/energyexplained/units-and-calculators/energy-conversion-calculators.php
A27: N2O | C27: 0.098470135 | D27: 0.0053950635 | G27: 0.0051972445 | I27: density | J27: https://www.ic.gc.ca/eic/site/mc-mc.nsf/vwapj/VCF_Diesel.pdf/$file/VCF_Diesel.pdf
A28: electricity consumed | C28: 36.273733 | D28: 36.273733 | I28: 840 | J28: kg/m3
A31: Fertilizer credit | D31: quality sheet compost | E31: quality sheet AD | F31: literature compost | G31: literature digestate | H31: NS | I31: unit
A32: nutrient supply from urea | B32: inorganic nitrogen fertiliser, as N | D32: 2.3344288 | E32: 8.3638 | F32: 0.295288 | G32: =620*0.4 -> 248 | H32: 1.7808 | I32: kg
A33: nutrient supply from monoammonium phosphate | B33: inorganic phosphorus fertiliser, as P2O5 | D33: 0.62187653 | E33: 8.835 | F33: 0.168736 | H33: 1.0176 | I33: kg
A34: nutrient supply from potassium nitrate | B34: inorganic potassium fertiliser, as K2O | D34: 0.014530974 | E34: 0.7657 | F34: 0.253104 | H34: 1.5264 | I34: kg

Sheet Transportation
A1: Transportation Distance | C1: Montreal-est TS Adress: | D1: 9000, place Marien, Montréal-Est
A2: note: assume all collection routes are the same and only consider distance from transfer station to facility, assume mtl-est transfer station (bc shared for both SSO and RW)
A3: Facility | B3: Distance | C3: units | D3: Address | E3: Note
A4: Landfill_saint sophie | B4: 45 | C4: km | D4: 2535, 1re Rue, Ste-Sophie (Qc) J0R 1S0
A5: Landfill_terrebonne | B5: 32 | C5: km | D5: 3779, chemin des 40 Arpents, Lachenaie, QC J6V 9T6
A6: Landfill_saint_thomas | B6: 74 | C6: km | D6: 1001, Chemin St-Joseph, Saint-Thomas, QC J0K 3L0
A7: Landfill_lachute | B7: 77.4 | C7: km | D7: 6985, chemin des Sources, Lachute
A8: Landfill_st-nicephore | B8: 123 | C8: km | D8: 25, rue Gagnon, St-Nicéphore (Qc) J2A 3H3
A9: Landfill_cecile_de_milton | B9: 96 | C9: km | D9: 702 route 137 sud, Sainte-Cécile-de-Milton, QC J0E 2C0
A10: Composter_casselman | B10: 133 | C10: km | D10: 908 Aurele Rd, Casselman, ON K0A 1M0 | E10: not sure…
A11: Composter_complexe enviro st Michel | B11: 6 | C11: km | D11: 2235 Rue Michel-Jurdant, Montréal, QC H1Z 4N1
A12: Composter_terrebonne | B12: 32 | C12: km | D12: =D5 -> 3779, chemin des 40 Arpents, Lachenaie, QC J6V 9T6
A13: Composter_saint thomas | B13: 74 | C13: km | D13: =D6 -> 1001, Chemin St-Joseph, Saint-Thomas, QC J0K 3L0 | E13: not sure…
A14: Closed-tunnel Composter | B14: 0 | C14: km | D14: 9091 Henri Bourassa Blvd W, Saint-Laurent, Quebec H4S 1P7 | E14: note: in reality I really don't think they would use the mtl est transfer station but why be specific for just this one
A15: AD | B15: 0 | C15: km | D15: can't find address currently

Sheet Landfill Equations (WARM)
A1: Warm model parameters (MSW landfilling of Mixed Organics; LFG recovery and electricity generation, typical collection, wet conditions (k=0.06))
A2: Process and parameters | B2: Equation (if applicable) | C2: Unit | D2: Value | E2: Notes | F2: Unit
A3: Electricity at grid | B3: electricity_from_CH4*CH4_recovered_for_energy*(1-system_down_time)*(final_yield_CH4*(1-moisture_content_mixed_organics)/tonne_to_sh_tn) | C3: kwh | D3: =D4*D5*(1-D6)*(D7*(1-D8)/D9) -> 87.325775
A4: electricity_from_CH4 | B4: CH4_calorific_value*net_capacity*kWh_per_BTU_CH4/(density_CH4_for_electricity/1000000) | D4: 3676.0684
A5: CH4_recovered_for_energy | D5: 0.49222093 | E5: %1. Source: Barlaz data
A6: system_down_time | D6: 0.03 | E6: 0.01
A7: final_yield_CH4 | B7: (1.24384729900016/GWP_CH4)*tonne_to_sh_tn/(1- moisture_content_mixed_organics) | D7: 0.15403929
A8: moisture_content_mixed_organics | D8: 0.64395917
A9: tonne_to_sh_tn | D9: 1.1023113 | E9: Conversion of units from metric tonnes to short tons
A10: CH4_calorific_value | D10: 1012 | E10: BTU/m3 methane. Source: EPA 2013. LMOP Benefits Calculator
A11: net_capacity | D11: 0.85 | E11: %1. Source: EPA 2005. LMOP Net capacity factor for generation units (availability, operating load, parasitic losses).
A12: density_CH4_for_electricity | D12: 20 | E12: g/ft3
A13: kWh_per_BTU_CH4 | D13: 8.5470085e-05 | E13: kWh of electricity generated per BTU methane. Source: EPA 2005. LMOP Benefits Calculator.
A14: GWP_CH4 | D14: 25 | E14: IPCC 2007
A15: Carbon | B15: C_storage_final *(1-moisture_content_mixed_organics)/tonne_to_sh_tn | D15: =D16 *(1-D8)/D9 -> 0.080744333 | E15: t
A16: C_storage_final | B16: 0.29606255454107*tonne_to_sh_tn/((1- moisture_content_mixed_organics)*C_to_CO2) | D16: 0.24998647
A17: C_to_CO2 | D17: 3.6666667 | E17: Conversion from carbon to CO2 according to molecular weights
A19: Methane | B19: CH4_emitted_final*final_yield_CH4*(1-moisture_content_mixed_organics)/tonne_to_sh_tn | D19: =D20*D7*(1-D8)/D9 -> 0.018120514 | E19: t
A20: CH4_emitted_final | D20: 0.36420295

Sheet Natural gas credit
B3: heating value | C3: units | D3: source
A4: biogas low | B4: 16 | C4: MJ/m3
A5: biogas high | B5: 28 | C5: MJ/m4
A6: Landfill gas | B6: 18.63 | C6: MJ/m3
A7: Natural gas | B7: 38.32 | C7: MJ/m3
A8: high efficiency of LFG relative to NG | B8: =B5/B7 -> 0.73068894 | C8: %
A9: low efficiency of LFG relative to NG | B9: =B4/B7 -> 0.41753653 | C9: %
A10: Annual production of GNR from AD | B10: 2579984 | C10: m3 | D10: GHG report City
A11: Facility capacity | B11: 60000 | C11: t OW annually | D11: sensitivity, 50, 60 %
A12: Annual production of RNG from landfill | B12: 400.27963 | C12: m3/ton OFMSW
A13: Annual production of RNG from AD | B13: =B10/B11 -> 42.999733 | C13: m3/ton OFMSW
G14: =2649/B12 -> 6.6178737 | H14: MJ/m3 | I14: LFG heating value
A15: Avoided Natural gas AD high | B15: =B8*B13 -> 31.419429 | C15: m3/t OW
A16: Avoided Natural gas AD low | B16: =B13*B9 -> 17.95396
A17: Avoided Natural gas landfill high | B17: =B12*B8 -> 292.47989 | C17: m3/t OW
A18: Avoided Natural gas landfill low | B18: =B12*B9 -> 167.13137

Sheet Fertilizer credit for compost
C1: compost ontario | D1: digestate
C2: on a wet basis | D2: 0.81 | E2: moisture content
A3: 1 | B3: t dry compost | D3: 1 | E3: t dry digestate | G3: inorganic nitrogen fertiliser, as N | H3: nutrient supply from urea | I3: kilogram | J3: ='Fertilizer credit for compost'!A15 -> 0.295288 | K3: RNA | L3: ecoinvent-3.8-cutoff | M3: substitution | O3: output
A4: 2.5 | B4: t wet compost | C4: 1 | D4: =D3/(1-D2) -> 5.2631579 | E4: t wet digestate | G4: inorganic phosphorus fertiliser, as P2O5 | H4: nutrient supply from monoammonium phosphate | I4: kilogram | J4: ='Fertilizer credit for compost'!A13 -> 0.168736 | K4: RNA | L4: ecoinvent-3.8-cutoff | M4: substitution | O4: output
A5: 4 | B5: kg P2O5 | C5: =13*0.4536 -> 5.8968 | D5: =75000*(1000/(10^6)) -> 75 | E5: kg P2O5 | G5: inorganic potassium fertiliser, as K2O | H5: nutrient supply from potassium chloride | I5: kilogram | J5: ='Fertilizer credit for compost'!A14 -> 0.253104 | K5: RNA | L5: ecoinvent-3.8-cutoff | M5: substitution | O5: output
A6: 6 | B6: kg K2O | C6: =16*0.4536 -> 7.2576 | D6: =6500*(1000/(10^6)) -> 6.5 | E6: kg K2O
A7: 7 | B7: kg N | C7: =48.8*0.4536 -> 22.13568 | D7: =71000*(1000/(10^6)) -> 71 | E7: kg N/ t dry compst
A9: source | B9: https://doi.org/10.1016/j.jclepro.2016.06.150
A10: Terrebonne compost
A11: 1 | B11: t OW
A12: 0.10546 | B12: t wet compost
A13: =$A$12/$A$4*A5 -> 0.168736 | B13: kg P2O5
A14: =$A$12/$A$4*A6 -> 0.253104 | B14: kg K2O
A15: =$A$12/$A$4*A7 -> 0.295288 | B15: kg N
A19: NS compost
A20: 1 | B20: t OW | G20: inorganic nitrogen fertiliser, as N | H20: nutrient supply from urea | I20: kilogram | J20: 1.7808 | K20: RNA | L20: ecoinvent-3.8-cutoff | M20: substitution | O20: output
A21: 0.636 | B21: t wet compost | G21: inorganic phosphorus fertiliser, as P2O5 | H21: nutrient supply from monoammonium phosphate | I21: kilogram | J21: 1.0176 | K21: RNA | L21: ecoinvent-3.8-cutoff | M21: substitution | O21: output
A22: =$A$21/$A$4*A5 -> 1.0176 | B22: kg P2O5 | G22: inorganic potassium fertiliser, as K2O | H22: nutrient supply from potassium chloride | I22: kilogram | J22: 1.5264 | K22: RNA | L22: ecoinvent-3.8-cutoff | M22: substitution | O22: output
A23: =$A$21/$A$4*A6 -> 1.5264 | B23: kg K2O
A24: =$A$21/$A$4*A7 -> 1.7808 | B24: kg N
A27: nutrient sheets
A28: compost
A29: 1 | B29: t OW
A30: 0.10546 | B30: t wet compost
A31: =A30*C7 -> 2.3344288 | B31: kg N
A32: =A30*C5 -> 0.62187653 | B32: kg P2O5
A33: =A30/C6 -> 0.014530974 | B33: kg K2O
A35: digestate
A36: 1 | B36: t OW
A37: 0.235 | B37: t wet digestate
A38: =A37/D4*D7 -> 3.17015 | B38: kg N
A39: =A37/D4*D5 -> 3.34875 | B39: kg P2O5
A40: =A37/D4*D6 -> 0.290225 | B40: kg K2O
A42: city compost
A43: 1 | B43: =B36 -> t OW
A44: 0.17406036 | B44: =B30 -> t wet compost | C44: =A44*1000 -> 174.06036
A45: =A44*C7 -> 3.8529443 | B45: kg N
A46: =A44*C5 -> 1.0263991 | B46: kg P2O5
A47: =A44*C6 -> 1.2632604 | B47: kg K2O

Sheet Boldrin
A3: Dry matter flows
B9: Composting windrow | C9: Composting Tunnel | D9: AD
A10: Tsout,x
A11: Tsbiof
A12: TCxf
A13: total weight of fraction
A14: TSf | B14: 0.95 | C14: 0.95 | D14: 0
A20: Parameter | B20: Definition | C20: unit | D20: CW | E20: CT | F20: AD
A21: Cair | B21: The amount of C-containing gaseous emissions (Cair, expressed as kg of C) | C21: kg C
A22: Mt | B22: input waste mass | C22: kg | D22: 1000 | E22: 1000 | F22: 1000
A23: mf | B23: mf (0–1) is the mass fraction of the waste material fraction f in the waste | C23: 0-1 | D23: 1 | E23: 1 | F23: 1
A24: TSf | B24: dry matter content (fraction of TS) of fraction f | C24: 0-1 | D24: 0.95 | E24: 0.95
A25: Cf | B25: carbon content (fraction of TS) for fraction f, | C25: 0-1
A26: Vsdegf | B26: VS degradation ratio for fraction f (user defined) | C26: 0-1
A33: CO2
A34: Cair
A35: CH4degr
A36: CH4remov
A37: molar_CO2 | D37: 44.01
A38: molac_C | D38: 12

Sheet Results
A1: Contributions by %
A3: name | B3: input | C3: type | D3: amount | E3: contribution | H3: name | I3: input | J3: type | K3: amount | L3: contribution | O3: name | P3: input | Q3: type | R3: amount | S3: contribution | V3: name | W3: input | X3: type | Y3: amount | Z3: contribution | AD3: name | AE3: input | AF3: type | AG3: amount | AH3: contribution | AK3: name | AL3: input | AM3: type | AN3: amount | AO3: contribution
A4: 0 | B4: Composter_terrebonne | C4: (OWM Facilities, dfc455135f96be2fc69fe163de47a... | D4: production | E4: 1 | F4: 109.65238 | H4: 0 | I4: Composter_casselman | J4: (OWM Facilities, eeb262dba20ea97b736f102578f01... | K4: production | L4: 1 | M4: 120.14859 | O4: 5 | P4: Dinitrogen monoxide | Q4: (ecoinvent-3.9.1-biosphere, 20185046-64bb-4c09... | R4: biosphere | S4: 0.205081 | T4: 55.987121 | V4: 2 | W4: market for heat, central or small-scale, other... | X4: (ecoinvent-3.9.1-cutoff, 9dd857c4552aa90cb27ef... | Y4: technosphere | Z4: 241.6 | AA4: 31.178391 | AB4: =AA4 -> 31.178391 | AC4: =AB4/AB25 -> 0.38223506 | AD4: 3 | AE4: Methane, non-fossil | AF4: (ecoinvent-3.9.1-biosphere, da1157e2-7593-4dfd... | AG4: biosphere | AH4: 4.147995 | AI4: 111.99586 | AK4: 0 | AL4: Landfill_lachute_HOC | AM4: (OWM Facilities, 0d4738c3dff15eb16ca260d229651... | AN4: production | AO4: 1 | AP4: 123.59206
A5: 6 | B5: Dinitrogen monoxide | C5: (ecoinvent-3.9.1-biosphere, 20185046-64bb-4c09... | D5: biosphere | E5: 0.224541 | F5: 61.299793 | H5: 6 | I5: Dinitrogen monoxide | J5: (ecoinvent-3.9.1-biosphere, 20185046-64bb-4c09... | K5: biosphere | L5: 0.224541 | M5: 61.299793 | O5: 0 | P5: Closed_composter_city_0702 | Q5: (OWM Facilities, f23aff46542d30ba1117f5429ebe0... | R5: production | S5: 1 | T5: 41.264986 | V5: 0 | W5: AD_city | X5: (OWM Facilities, 9b4a06dcebd1ead55bfafa108a0b2... | Y5: production | Z5: 1 | AA5: 14.457275 | AB5: =AA5 -> 14.457275 | AC5: =AB5/$AB$25 -> 0.17724062 | AD5: 0 | AE5: Landfill_terrebonne_HOC | AF5: (OWM Facilities, 93b5a70f68a512730247a3eeca34c... | AG5: production | AH5: 1 | AI5: 32.620892 | AJ5: =AI5/242 -> 0.13479707 | AK5: 3 | AL5: Methane, non-fossil | AM5: (ecoinvent-3.9.1-biosphere, da1157e2-7593-4dfd... | AN5: biosphere | AO5: 4.147995 | AP5: 111.99586
A6: 7 | B6: Methane, non-fossil | C6: (ecoinvent-3.9.1-biosphere, da1157e2-7593-4dfd... | D6: biosphere | E6: 1.627925 | F6: 43.953973 | H6: 7 | I6: Methane, non-fossil | J6: (ecoinvent-3.9.1-biosphere, da1157e2-7593-4dfd... | K6: biosphere | L6: 1.627925 | M6: 43.953973 | O6: 1 | P6: market for electricity, low voltage | Q6: (ecoinvent-3.9.1-cutoff, ab2025e93043973cf4bb5... | R6: technosphere | S6: 121.10967 | T6: 3.227688 | V6: 3 | W6: market for machine operation, diesel, >= 74.57... | X6: (ecoinvent-3.9.1-cutoff, d3006729097835754ee0c... | Y6: technosphere | Z6: 0.352113 | AA6: 8.986135 | AB6: =AA6 -> 8.986135 | AC6: =AB6/$AB$25 -> 0.11016655 | AD6: 1 | AE6: market for transport, freight, lorry >32 metri... | AF6: (ecoinvent-3.9.1-cutoff, e76596f45bcb935639d77... | AG6: technosphere | AH6: 32 | AI6: 3.325529 | AK6: 1 | AL6: market for transport, freight, lorry >32 metri... | AM6: (ecoinvent-3.9.1-cutoff, e76596f45bcb935639d77... | AN6: technosphere | AO6: 77.4 | AP6: 8.043624 | AQ6: =AP6/AP4 -> 0.065082048
A7: 3 | B7: market for transport, freight, lorry >32 metri... | C7: (ecoinvent-3.9.1-cutoff, e76596f45bcb935639d77... | D7: technosphere | E7: 32 | F7: 3.325529 | H7: 3 | I7: market for transport, freight, lorry >32 metri... | J7: (ecoinvent-3.9.1-cutoff, e76596f45bcb935639d77... | K7: technosphere | L7: 133 | M7: 13.821731 | N7: =M7/M4 -> 0.11503865 | O7: 2 | P7: market for natural gas, high pressure | Q7: (ecoinvent-3.9.1-cutoff, ab6a81dd5e1ed8e4c69d8... | R7: technosphere | S7: 4.347469 | T7: 1.975076 | V7: 8 | W7: Dinitrogen monoxide | X7: (ecoinvent-3.9.1-biosphere, 20185046-64bb-4c09... | Y7: biosphere | Z7: 0.001667 | AA7: 0.455 | AB7: =AA7 -> 0.455 | AC7: =AB7/$AB$25 -> 0.0055781247 | AD7: 5 | AE7: Dinitrogen monoxide | AF7: (ecoinvent-3.9.1-biosphere, 20185046-64bb-4c09... | AG7: biosphere | AH7: 0.009231 | AI7: 2.519938 | AJ7: =AI7/242 -> 0.010412967 | AK7: 5 | AL7: Dinitrogen monoxide | AM7: (ecoinvent-3.9.1-biosphere, 20185046-64bb-4c09... | AN7: biosphere | AO7: 0.009231 | AP7: 2.519938
A8: 2 | B8: market for diesel | C8: (ecoinvent-3.9.1-cutoff, b613a0e604fce45d41460... | D8: technosphere | E8: 2.532006 | F8: 2.081563 | H8: 2 | I8: market for diesel | J8: (ecoinvent-3.9.1-cutoff, b613a0e604fce45d41460... | K8: technosphere | L8: 2.532006 | M8: 2.081563 | O8: 9 | P8: market for sulfuric acid | Q8: (ecoinvent-3.9.1-cutoff, bd7dddfe46e52010e6555... | R8: technosphere | S8: 1.326439 | T8: 0.233367 | V8: 1 | W8: market for electricity, low voltage | X8: (ecoinvent-3.9.1-cutoff, ab2025e93043973cf4bb5... | Y8: technosphere | Z8: 2.135 | AA8: 0.0569 | AB8: =AA8 -> 0.0569 | AC8: =AB8/$AB$25 -> 0.00069757208 | AD8: 6 | AE8: market for electricity, low voltage | AF8: (ecoinvent-3.9.1-cutoff, ab2025e93043973cf4bb5... | AG8: technosphere | AH8: 64.423796 | AI8: 1.716956 | AK8: 6 | AL8: market for electricity, low voltage | AM8: (ecoinvent-3.9.1-cutoff, ab2025e93043973cf4bb5... | AN8: technosphere | AO8: 64.423796 | AP8: 1.716956
A9: 4 | B9: treatment of wastewater, average, wastewater t... | C9: (ecoinvent-3.9.1-cutoff, c64fb2a247373a9696f5c... | D9: technosphere | E9: -7.289155 | F9: 1.478784 | H9: 4 | I9: treatment of wastewater, average, wastewater t... | J9: (ecoinvent-3.9.1-cutoff, c64fb2a247373a9696f5c... | K9: technosphere | L9: -7.289155 | M9: 1.478784 | O9: 4 | P9: treatment of wastewater, average, wastewater t... | Q9: (ecoinvent-3.9.1-cutoff, c64fb2a247373a9696f5c... | R9: technosphere | S9: -0.064298 | T9: 0.013044 | V9: 16 | W9: treatment of wastewater, average, wastewater t... | X9: (ecoinvent-3.9.1-cutoff, c64fb2a247373a9696f5c... | Y9: technosphere | Z9: -0.225 | AA9: 0.045647 | AB9: =AA9 -> 0.045647 | AC9: =AB9/$AB$25 -> 0.00055961463 | AD9: 2 | AE9: market for diesel | AF9: (ecoinvent-3.9.1-cutoff, b613a0e604fce45d41460... | AG9: technosphere | AH9: 1.223395 | AI9: 1.005754 | AK9: 2 | AL9: market for diesel | AM9: (ecoinvent-3.9.1-cutoff, b613a0e604fce45d41460... | AN9: technosphere | AO9: 1.223395 | AP9: 1.005754
A10: 1 | B10: market for electricity, low voltage | C10: (ecoinvent-3.9.1-cutoff, ab2025e93043973cf4bb5... | D10: technosphere | E10: 1.677212 | F10: 0.044699 | H10: 1 | I10: market for electricity, low voltage | J10: (ecoinvent-3.9.1-cutoff, ab2025e93043973cf4bb5... | K10: technosphere | L10: 1.677212 | M10: 0.044699 | O10: 3 | P10: market for transport, freight, lorry >32 metri... | Q10: (ecoinvent-3.9.1-cutoff, e76596f45bcb935639d77... | R10: technosphere | S10: 0 | T10: 0 | V10: 10 | W10: Methane, non-fossil | X10: (ecoinvent-3.9.1-biosphere, da1157e2-7593-4dfd... | Y10: biosphere | Z10: 0.001667 | AA10: 0.045 | AB10: =AA10 -> 0.045 | AC10: =AB10/$AB$25 -> 0.00055168266 | AD10: 8 | AE10: treatment of wastewater, average, wastewater t... | AF10: (ecoinvent-3.9.1-cutoff, c64fb2a247373a9696f5c... | AG10: technosphere | AH10: -2.297966 | AI10: 0.466199 | AK10: 8 | AL10: treatment of wastewater, average, wastewater t... | AM10: (ecoinvent-3.9.1-cutoff, c64fb2a247373a9696f5c... | AN10: technosphere | AO10: -2.297966 | AP10: 0.466199
A11: 5 | B11: Ammonia | C11: (ecoinvent-3.9.1-biosphere, 87883a4e-1e3e-4c9d... | D11: biosphere | E11: 0.000561 | F11: 0 | H11: 5 | I11: Ammonia | J11: (ecoinvent-3.9.1-biosphere, 87883a4e-1e3e-4c9d... | K11: biosphere | L11: 0.000561 | M11: 0 | O11: 7 | P11: nutrient supply from monoammonium phosphate | Q11: (ecoinvent-3.9.1-cutoff, dc813b650a2573a1a08e6... | R11: substitution | S11: 1.026399 | T11: -1.733834 | U11: =T11/T5 -> -0.042017075 | V11: 4 | W11: market for tap water | X11: (ecoinvent-3.9.1-cutoff, e10c44bab6fdc65dc71e5... | Y11: technosphere | Z11: 225 | AA11: 0.017243 | AB11: =AA11 -> 0.017243 | AC11: =AB11/$AB$25 -> 0.00021139254 | AD11: 7 | AE11: Carbon dioxide, non-fossil | AF11: (ecoinvent-3.9.1-biosphere, eba59fd6-f37e-41dc... | AG11: biosphere | AH11: 38.489348 | AI11: 0 | AJ11: =SUM(AI4:AI11)+(-AI12) -> 242.06048 | AK11: 7 | AL11: Carbon dioxide, non-fossil | AM11: (ecoinvent-3.9.1-biosphere, eba59fd6-f37e-41dc... | AN11: biosphere | AO11: 38.489348 | AP11: 0
A12: 8 | B12: NMVOC, non-methane volatile organic compounds | C12: (ecoinvent-3.9.1-biosphere, d3260d0e-8203-4cbb... | D12: biosphere | E12: 0.001085 | F12: 0 | H12: 8 | I12: NMVOC, non-methane volatile organic compounds | J12: (ecoinvent-3.9.1-biosphere, d3260d0e-8203-4cbb... | K12: biosphere | L12: 0.001085 | M12: 0 | O12: 8 | P12: nutrient supply from potassium nitrate | Q12: (ecoinvent-3.9.1-cutoff, 39b3113bf30886d67d804... | R12: substitution | S12: 1.26326 | T12: -6.740163 | U12: =T12/T5 -> -0.16333855 | V12: 7 | W12: Carbon dioxide, non-fossil | X12: (ecoinvent-3.9.1-biosphere, eba59fd6-f37e-41dc... | Y12: biosphere | Z12: 0 | AA12: 0 | AB12: =AA12 -> 0 | AD12: 4 | AE12: market for natural gas, high pressure | AF12: (ecoinvent-3.9.1-cutoff, ab6a81dd5e1ed8e4c69d8... | AG12: substitution | AH12: 194.60359 | AI12: -88.409345 | AJ12: =AI12/AJ11 -> -0.3652366 | AK12: 4 | AL12: market for electricity, low voltage | AM12: (ecoinvent-3.9.1-cutoff, ab2025e93043973cf4bb5... | AN12: substitution | AO12: 80.908166 | AP12: -2.15628
A13: 10 | B13: nutrient supply from monoammonium phosphate | C13: (ecoinvent-3.9.1-cutoff, dc813b650a2573a1a08e6... | D13: substitution | E13: 0.168736 | F13: -0.285036 | H13: 10 | I13: nutrient supply from monoammonium phosphate | J13: (ecoinvent-3.9.1-cutoff, dc813b650a2573a1a08e6... | K13: substitution | L13: 0.168736 | M13: -0.285036 | O13: 6 | P13: nutrient supply from urea | Q13: (ecoinvent-3.9.1-cutoff, de5f22c1d190c5ecb97d2... | R13: substitution | S13: 3.852944 | T13: -11.697312 | U13: =T13/T5 -> -0.28346822 | V13: 6 | W13: Ammonia | X13: (ecoinvent-3.9.1-biosphere, 87883a4e-1e3e-4c9d... | Y13: biosphere | Z13: 0.1456 | AA13: 0 | AB13: =AA13 -> 0
A14: 9 | B14: nutrient supply from urea | C14: (ecoinvent-3.9.1-cutoff, de5f22c1d190c5ecb97d2... | D14: substitution | E14: 0.295288 | F14: -0.896477 | H14: 9 | I14: nutrient supply from urea | J14: (ecoinvent-3.9.1-cutoff, de5f22c1d190c5ecb97d2... | K14: substitution | L14: 0.295288 | M14: -0.896477 | V14: 9 | W14: Hydrogen sulfide | X14: (ecoinvent-3.9.1-biosphere, 20d4d821-f4f7-4017... | Y14: biosphere | Z14: 0.0896 | AA14: 0 | AB14: =AA14 -> 0
A15: 11 | B15: nutrient supply from potassium nitrate | C15: (ecoinvent-3.9.1-cutoff, 39b3113bf30886d67d804... | D15: substitution | E15: 0.253104 | F15: -1.350444 | H15: 11 | I15: nutrient supply from potassium nitrate | J15: (ecoinvent-3.9.1-cutoff, 39b3113bf30886d67d804... | K15: substitution | L15: 0.253104 | M15: -1.350444 | V15: 5 | W15: market for transport, freight, lorry >32 metri... | X15: (ecoinvent-3.9.1-cutoff, e76596f45bcb935639d77... | Y15: technosphere | Z15: 0 | AA15: 0 | AB15: =AA15 -> 0
V16: 11 | W16: NMVOC, non-methane volatile organic compounds | X16: (ecoinvent-3.9.1-biosphere, d3260d0e-8203-4cbb... | Y16: biosphere | Z16: 0.426 | AA16: 0 | AB16: =AA16 -> 0
V17: 12 | W17: Nitrate | X17: (ecoinvent-3.9.1-biosphere, 5e7cf95c-9cc3-4479... | Y17: biosphere | Z17: 0.00297 | AA17: 0 | AB17: =AA17 -> 0
V18: 13 | W18: Nitrite | X18: (ecoinvent-3.9.1-biosphere, 9f5bfac4-cbb6-4b38... | Y18: biosphere | Z18: 9.3e-05 | AA18: 0 | AB18: =AA18 -> 0
V19: 14 | W19: Nitrogen, organic bound | X19: (ecoinvent-3.9.1-biosphere, a703733d-fabc-487b... | Y19: biosphere | Z19: 0.000109 | AA19: 0 | AB19: =AA19 -> 0
V20: 15 | W20: Phosphorus | X20: (ecoinvent-3.9.1-biosphere, d761f94e-517d-41cf... | Y20: biosphere | Z20: 7e-05 | AA20: 0 | AB20: =AA20 -> 0
V21: 20 | W21: nutrient supply from potassium nitrate | X21: (ecoinvent-3.9.1-cutoff, 39b3113bf30886d67d804... | Y21: substitution | Z21: 0.290225 | AA21: -1.548504 | AB21: =-AA21 -> 1.548504
V22: 19 | W22: nutrient supply from monoammonium phosphate | X22: (ecoinvent-3.9.1-cutoff, dc813b650a2573a1a08e6... | Y22: substitution | Z22: 3.34875 | AA22: -5.656842 | AB22: =-AA22 -> 5.656842
V23: 17 | W23: market for natural gas, high pressure | X23: (ecoinvent-3.9.1-cutoff, ab6a81dd5e1ed8e4c69d8... | Y23: substitution | Z23: 20.905142 | AA23: -9.497306 | AB23: =-AA23 -> 9.497306
V24: 18 | W24: nutrient supply from urea | X24: (ecoinvent-3.9.1-cutoff, de5f22c1d190c5ecb97d2... | Y24: substitution | Z24: 3.17015 | AA24: -9.624389 | AB24: =-AA24 -> 9.624389 | AD24: =AB24/AB25 -> 0.1179913
AB25: =SUM(AB4:AB24) -> 81.568632
