Workbook

Sheet LCI
A1: Database | B1: OWM Facilities
A4: Activity | B4: Composter_casselman
A5: comment | B5: Data provided by waste connections
A6: location | B6: CA-QC
A7: production amount | B7: 1
A8: unit | B8: tonne
A10: Exchanges
A11: name | B11: reference product | C11: unit | D11: amount | E11: location | F11: database | G11: type | H11: categories | I11: comment
A12: =B4 -> Composter_casselman | B12: OFMSW | C12: tonne | D12: 1 | E12: CA-QC | F12: =$B$1 -> OWM Facilities | G12: production | I12: output
A13: market for electricity, low voltage | B13: electricity, low voltage | C13: kilowatt hour | D13: 1.6772117 | E13: CA-QC | F13: ecoinvent-3.9.1-cutoff | G13: technosphere | I13: input
A14: market for diesel | B14: diesel | C14: kilogram | D14: 2.5320056 | E14: RoW | F14: ecoinvent-3.9.1-cutoff | G14: technosphere | I14: input
A15: market for transport, freight, lorry >32 metric ton, EURO5 | B15: transport, freight, lorry >32 metric ton, EURO5 | C15: ton kilometer | D15: =Transportation!B10 -> 133 | E15: RER | F15: ecoinvent-3.9.1-cutoff | G15: technosphere | I15: input
A16: treatment of wastewater, average, wastewater treatment | B16: wastewater, average | C16: cubic meter | D16: -7.2891552 | E16: CA-QC | F16: ecoinvent-3.9.1-cutoff | G16: technosphere | I16: output
A17: Ammonia | C17: kilogram | D17: 0.0005613534 | F17: ecoinvent-3.9-biosphere | G17: biosphere | H17: air | I17: output
A18: Dinitrogen monoxide | C18: kilogram | D18: 0.22454136 | F18: ecoinvent-3.9-biosphere | G18: biosphere | H18: air | I18: output
A19: Methane, non-fossil | C19: kilogram | D19: 1.6279249 | F19: ecoinvent-3.9-biosphere | G19: biosphere | H19: air | I19: output
A20: NMVOC, non-methane volatile organic compounds | C20: kilogram | D20: 0.0010852832 | F20: ecoinvent-3.9-biosphere | G20: biosphere | H20: air | I20: output
A21: nutrient supply from urea | B21: inorganic nitrogen fertiliser, as N | C21: kilogram | D21: 0.295288 | E21: RNA | F21: ecoinvent-3.9.1-cutoff | G21: substitution
A22: nutrient supply from monoammonium phosphate | B22: inorganic phosphorus fertiliser, as P2O5 | C22: kilogram | D22: 0.168736 | E22: RNA | F22: ecoinvent-3.9.1-cutoff | G22: substitution
A23: nutrient supply from potassium nitrate | B23: inorganic potassium fertiliser, as K2O | C23: kilogram | D23: 0.253104 | E23: RNA | F23: ecoinvent-3.9.1-cutoff | G23: substitution
A31: Activity | B31: Composter_complexe enviro st Michel
A32: comment | B32: Data provided by waste connections
A33: location | B33: CA-QC
A34: production amount | B34: 1
A35: unit | B35: tonne
A37: Exchanges
A38: name | B38: reference product | C38: unit | D38: amount | E38: location | F38: database | G38: type | H38: categories | I38: comment
A39: =B31 -> Composter_complexe enviro st Michel | B39: OFMSW | C39: tonne | D39: 1 | E39: CA-QC | F39: =$B$1 -> OWM Facilities | G39: production | I39: output
A40: market for electricity, low voltage | B40: electricity, low voltage | C40: kilowatt hour | D40: 1.6772117 | E40: CA-QC | F40: ecoinvent-3.9.1-cutoff | G40: technosphere | I40: input
A41: market for diesel | B41: diesel | C41: kilogram | D41: 2.5320056 | E41: RoW | F41: ecoinvent-3.9.1-cutoff | G41: technosphere | I41: input
A42: market for transport, freight, lorry >32 metric ton, EURO5 | B42: transport, freight, lorry >32 metric ton, EURO5 | C42: ton kilometer | D42: =Transportation!B11 -> 6 | E42: RER | F42: ecoinvent-3.9.1-cutoff | G42: technosphere | I42: input
A43: treatment of wastewater, average, wastewater treatment | B43: wastewater, average | C43: cubic meter | D43: -7.2891552 | E43: CA-QC | F43: ecoinvent-3.9.1-cutoff | G43: technosphere | I43: output
A44: Ammonia | C44: kilogram | D44: 0.0005613534 | F44: ecoinvent-3.9-biosphere | G44: biosphere | H44: air | I44: output
A45: Dinitrogen monoxide | C45: kilogram | D45: 0.22454136 | F45: ecoinvent-3.9-biosphere | G45: biosphere | H45: air | I45: output
A46: Methane, non-fossil | C46: kilogram | D46: 1.6279249 | F46: ecoinvent-3.9-biosphere | G46: biosphere | H46: air | I46: output
A47: NMVOC, non-methane volatile organic compounds | C47: kilogram | D47: 0.0010852832 | F47: ecoinvent-3.9-biosphere | G47: biosphere | H47: air | I47: output
A48: nutrient supply from urea | B48: inorganic nitrogen fertiliser, as N | C48: kilogram | D48: 0.295288 | E48: RNA | F48: ecoinvent-3.9.1-cutoff | G48: substitution
A49: nutrient supply from monoammonium phosphate | B49: inorganic phosphorus fertiliser, as P2O5 | C49: kilogram | D49: 0.168736 | E49: RNA | F49: ecoinvent-3.9.1-cutoff | G49: substitution
A50: nutrient supply from potassium nitrate | B50: inorganic potassium fertiliser, as K2O | C50: kilogram | D50: 0.253104 | E50: RNA | F50: ecoinvent-3.9.1-cutoff | G50: substitution
A58: Activity | B58: Composter_terrebonne
...

Sheet GHGRP Landfill Gas Inventory
A1: GHG Emissions for Landfills from GHGRP Landfill Gas Inventory
F2: Unit
D3: Landfilled organic waste at Lachenaie | E3: 313091.04 | F3: tonne
A4: Lachenaie (Terrebonne) Landfill GHG emissions from GHGRP inventory
A5: Assume other landfills are approximated by this data
A6: Gas | B6: Sum (tonnes) | C6: Sum (tonnes CO2 eq ) | D6: tonnes/tonne organic waste in landfill | E6: Units
A7: CO2 | B7: 12050.67 | C7: 12 051 | D7: =B7/$E$3*1000 -> 38.489348 | E7: kg/tonne OFMSW
A8: CH4 | B8: 1298.7 | C8: 36 364 | D8: =B8/$E$3*1000 -> 4.1479948 | E8: kg/tonne OFMSW
A9: N2O | B9: 2.89 | C9: 766 | D9: =B9/$E$3*1000 -> 0.0092305421 | E9: kg/tonne OFMSW
A10: HFCs | B10: 0 | C10: 0
A11: PFCs | B11: 0 | C11: 0
A12: SF6 | B12: 0 | C12: 0
A13: Total : | C13: 49 180
A16: Landfill Name | B16: Current LFG Management System (2022) | C16: GHGRP ID | D16: NPRI ID
A17: Complexe Enviro Connexions | B17: RNG | C17: G10401 | D17: 6370
A18: LET de Lachute | B18: Electricity | C18: G10538 | D18: 27915
A19: LET de Ste-Sophie | B19: Direct Use (RNG under development) | C19: G10344 | D19: 6173
A20: LET de St-Nicéphore | B20: Electricity | C20: G10572 | D20: 6171
A21: LET de St-Thomas (Rive-Nord) | B21: RNG | C21: G10730
A22: LET Roland Thibault Inc | B22: Electricity | C22: G10633 | D22: 31585

Sheet Transportation
A1: Transportation Distance
A3: Facility | B3: Distance | C3: Units | D3: Address | E3: Note
A4: Landfill_saint sophie | B4: 45 | C4: km | D4: N/A | E4: Obtained from 2024 report from the City of Montreal
A5: Landfill_terrebonne | B5: 32 | C5: km | D5: N/A | E5: Obtained from 2024 report from the City of Montreal
A6: Landfill_saint_thomas | B6: 74 | C6: km | D6: N/A | E6: Obtained from 2024 report from the City of Montreal
A7: Landfill_lachute | B7: 77.4 | C7: km | D7: 6985, chemin des Sources, Lachute | E7: Distance on google maps from Montreal-Est transfer station to Lachute Landfill
A8: Landfill_st-nicephore | B8: 123 | C8: km | D8: N/A | E8: Obtained from 2024 report from the City of Montreal
A9: Landfill_cecile_de_milton | B9: 96 | C9: km | D9: N/A | E9: Obtained from 2024 report from the City of Montreal
A10: Composter_casselman | B10: 133 | C10: km | D10: N/A | E10: Obtained from 2024 report from the City of Montreal
A11: Composter_complexe enviro st Michel | B11: 6 | C11: km | D11: N/A | E11: Obtained from 2024 report from the City of Montreal
A12: Composter_terrebonne | B12: 32 | C12: km | D12: N/A | E12: Obtained from 2024 report from the City of Montreal
A13: Composter_saint thomas | B13: 74 | C13: km | D13: N/A | E13: Obtained from 2024 report from the City of Montreal
A14: Closed-tunnel Composter | B14: 0 | C14: km | D14: N/A | E14: Obtained from 2024 report from the City of Montreal
A15: AD | B15: 0 | C15: km | D15: N/A | E15: Obtained from 2024 report from the City of Montreal
A17: note:
A18: Montreal-est TS Adress: | B18: 9000, place Marien, Montréal-Est

Sheet Natural gas credit
A1: Avoided fossil natural gas from landfills and anaerobic digestion (AD)
C2: units
A3: Biogas calorific value | B3: 18.63 | C3: MJ/m3
A4: Natural gas calorific value | B4: 38.32 | C4: MJ/m3
A5: Efficiency of biogas relative to NG | B5: =B3/B4 -> 0.4861691 | C5: %
A6: Annual production of GNR from AD | B6: 2579984 | C6: m3
A7: Facility capacity | B7: 60000 | C7: t OW annually
A8: Annual production of RNG from landfill | B8: 400.27963 | C8: m3/ton OFMSW
A9: Annual production of RNG from AD | B9: =B6/B7 -> 42.999733 | C9: m3/ton OFMSW
A11: Avoided Natural gas AD | B11: =B6*B5/B7 -> 20.905142 | C11: m3/t OW
A12: Avoided Natural gas landfill | B12: =B8*B5 -> 194.60359 | C12: m3/t OW

Sheet Fertilizer credit for compost
A1: Avoided synthetic fertilizer from compost and digestate
A2: Conversion of dry basis to wet
A3: Literature compost | C3: Windrow compost | D3: City compost final | F3: Digestate
A4: source | B4: https://doi.org/10.1016/j.jclepro.2016.06.150 | C4: on a wet basis | D4: 0.23 | E4: moisture content | F4: 0.81 | G4: moisture content
A5: 1 | B5: t dry compost | D5: 1 | E5: t dry compost | F5: 1 | G5: t dry digestate
A6: 2.5 | B6: t wet compost | C6: 1 | D6: =D5/(1-D4) -> 1.2987013 | E6: t wet compost | F6: =F5/(1-F4) -> 5.2631579 | G6: t wet digestate
A7: 4 | B7: kg P2O5 | C7: =13*0.4536 -> 5.8968 | D7: =6190/1000 -> 6.19 | E7: kg P2O5 | F7: =75000*(1000/(10^6)) -> 75 | G7: kg P2O5
A8: 6 | B8: kg K2O | C8: =16*0.4536 -> 7.2576 | D8: =9710/1000 -> 9.71 | E8: kg K2O | F8: =6500*(1000/(10^6)) -> 6.5 | G8: kg K2O
A9: 7 | B9: kg N | C9: =48.8*0.4536 -> 22.13568 | D9: =17/1000 -> 0.017 | E9: kg N/ t dry compost | F9: =71000*(1000/(10^6)) -> 71 | G9: kg N/ t dry compst
A11: Inventory calculations
A12: Literature compost
A13: 1 | B13: t OW
A14: 0.10546 | B14: t wet compost
A15: =$A$14/$A$6*A7 -> 0.168736 | B15: kg P2O5
A16: =$A$14/$A$6*A8 -> 0.253104 | B16: kg K2O
A17: =$A$14/$A$6*A9 -> 0.295288 | B17: kg N
A21: =C3 -> Windrow compost
A22: 1 | B22: t OW
A23: 0.10546 | B23: t wet compost
A24: =A23*C9 -> 2.3344288 | B24: kg N
A25: =A23*C7 -> 0.62187653 | B25: kg P2O5
A26: =A23/C8 -> 0.014530974 | B26: kg K2O
A28: =F3 -> Digestate
A29: 1 | B29: t OW
A30: 0.235 | B30: t wet digestate
A31: =A30/F6*F9 -> 3.17015 | B31: kg N
A32: =A30/F6*F7 -> 3.34875 | B32: kg P2O5
A33: =A30/F6*F8 -> 0.290225 | B33: kg K2O
A37: =D3 -> City compost final | B37: 1 t OW
A38: 0.37593223 | B38: t wet compost
A39: =(A38*D9)/D6 -> 0.0049209529 | B39: kg N
A40: =(A38*D7)/D6 -> 1.7918058 | B40: kg P2O5
A41: =(A38*D8)/D6 -> 2.8107325 | B41: kg K2O
